<?xml version="1.0"?>

<!-- XML namespaces -->
<robot xmlns:sensor="http://playerstage.sourceforge.net/gazebo/xmlschema/#sensor"
       xmlns:controller="http://playerstage.sourceforge.net/gazebo/xmlschema/#controller"
       xmlns:interface="http://playerstage.sourceforge.net/gazebo/xmlschema/#interface"
       xmlns:xacro="http://ros.org/wiki/xacro">

  <!-- Things that are needed only for Gazebo (not the physical robot).  These include
       sensor and controller plugin specifications -->
  <xacro:include filename="$(find aurobot_description)/urdf/pa10-green/shoulder/shoulder.gazebo.xacro"/>
  <xacro:include filename="$(find aurobot_description)/urdf/pa10-green/shoulder/shoulder.transmission.xacro"/>
  <xacro:include filename="$(find aurobot_description)/urdf/common.xacro"/>

 <!-- ============================   Shoulder   ============================ -->

  <xacro:macro name="pa10_green_shoulder" params="child">
    <!-- S1: Shoulder roll -->
    <link name="pa10_green_shoulder_roll_link">
      <inertial>
        <mass value="12.43"/>
        <origin xyz="0 0 0" rpy="0 0 0"/>
        <inertia ixx="1.00"  ixy="0"  ixz="0" iyy="1.00" iyz="0" izz="1.00"/>
      </inertial>
      <visual>
        <geometry>
          <!-- <mesh filename="package://aurobot_description/meshes/pa10-green/shoulder/S1.dae"/> -->
          <mesh filename="package://aurobot_description/meshes/pa10-green/shoulder/pa10_00.stl"/>
        </geometry>
        <material name="blue"/>
      </visual>
      <collision>
        <geometry>
          <!-- <mesh filename="package://aurobot_description/meshes/pa10-green/shoulder/S1.stl"/> -->
          <mesh filename="package://aurobot_description/meshes/pa10-green/shoulder/pa10_00.stl"/>
        </geometry>
      </collision>
    </link>
    <joint name="pa10_green_shoulder_roll_joint" type="revolute">
      <parent link="pa10_green_shoulder_roll_link"/>
      <child link="pa10_green_shoulder_lift_link"/>
      <!-- BRAYAN (12/07/2017): Segun el manual nos sobra 0.001 <origin xyz="0 0 0.201" rpy="0 0 0"/> -->
      <origin xyz="0 0 0.20" rpy="0 0 0"/>
      <axis xyz="0 0 1"/>
      <limit effort="1000.0" lower="-3.089232776" upper="3.089232776" velocity="0.1"/> 
      <cfm>0.7</cfm>
      <damping>10.0</damping>
    </joint>
    
    <!-- S2: Shoulder lift -->
    <link name="pa10_green_shoulder_lift_link">
      <inertial>
        <mass value="9.78"/>
        <origin xyz="0 0 0.115" rpy="0 0 0"/>
        <inertia ixx="0.110697"  ixy="0.000005"  ixz="0.000345" iyy="0.084268" iyz="0.000518" izz="0.054080"/>
      </inertial>
      <visual>
        <origin xyz="0 0 0.115" rpy="0 0 0"/>
        <geometry>
          <!-- <mesh filename="package://aurobot_description/meshes/pa10-green/shoulder/S2.dae"/> -->
          <mesh filename="package://aurobot_description/meshes/pa10-green/shoulder/pa10_01.stl"/>
        </geometry>
        <material name="green"/>
      </visual>
      <collision>
        <origin xyz="0 0 0.115" rpy="0 0 0"/>
        <geometry>
          <!-- <mesh filename="package://aurobot_description/meshes/pa10-green/shoulder/S2.stl" /> -->
          <mesh filename="package://aurobot_description/meshes/pa10-green/shoulder/pa10_01.stl"/>
        </geometry>
      </collision>
    </link>
    <joint name="pa10_green_shoulder_lift_joint" type="revolute">
      <parent link="pa10_green_shoulder_lift_link"/>
      <child link="pa10_green_upper_arm_roll_link"/>
      <origin xyz="0 0 0.115" rpy="0 0 0"/>
      <axis xyz="0 1 0"/>
      <limit effort="1000.0" lower="-1.5882496193" upper="1.5882496193" velocity="0.1"/>
      <cfm>0.7</cfm>
      <damping>10.0</damping>
    </joint>
    
    <!-- S3: Upperarm roll -->
    <link name="pa10_green_upper_arm_roll_link">
      <inertial>
        <mass value="8.41"/>
        <origin xyz="0 -0.0632 0" rpy="0 0 0"/>
        <inertia ixx="0.177079"  ixy="0.000257"  ixz="0.000005" iyy="0.018440" iyz="0.000005" izz="0.173903"/>
      </inertial>
      <visual>
        <geometry>
          <!-- <mesh filename="package://aurobot_description/meshes/pa10-green/shoulder/S3.dae" /> -->
          <mesh filename="package://aurobot_description/meshes/pa10-green/shoulder/pa10_02.stl"/>
        </geometry>
        <material name="blue"/>
      </visual>
      <collision>
        <geometry>
          <!-- <mesh filename="package://aurobot_description/meshes/pa10-green/shoulder/S3.stl" /> -->
          <mesh filename="package://aurobot_description/meshes/pa10-green/shoulder/pa10_02.stl"/>
        </geometry>
      </collision>
    </link>
    <joint name="pa10_green_upper_arm_roll_joint" type="revolute">
      <parent link="pa10_green_upper_arm_roll_link"/>
      <child link="${child}"/>
      <axis xyz="0 0 1"/>
      <origin xyz="0 0 0.325" rpy="0 0 0"/>
      <limit effort="1000.0" lower="-3.0368728985" upper="3.0368728985" velocity="0.2"/>
      <cfm>0.7</cfm>
      <damping>10.0</damping>
    </joint>

    <!-- extensions -->
    <xacro:pa10_green_shoulder_gazebo/>
    <xacro:pa10_green_shoulder_transmission/>
  </xacro:macro>
</robot>
