<?xml version="1.0"?>

<!-- XML namespaces -->
<robot xmlns:sensor="http://playerstage.sourceforge.net/gazebo/xmlschema/#sensor"
       xmlns:controller="http://playerstage.sourceforge.net/gazebo/xmlschema/#controller"
       xmlns:interface="http://playerstage.sourceforge.net/gazebo/xmlschema/#interface"
       xmlns:xacro="http://ros.org/wiki/xacro">

  <!-- Things that are needed only for Gazebo (not the physical robot). These include
       sensor and controller plugin specifications -->
  <xacro:include filename="$(find aurobot_description)/urdf/pa10-blue/forearm/forearm.gazebo.xacro"/>
  <xacro:include filename="$(find aurobot_description)/urdf/pa10-blue/forearm/forearm.transmission.xacro"/>
  <xacro:include filename="$(find aurobot_description)/urdf/common.xacro"/>

  <!-- ============================   Forearm   ============================ -->

  <xacro:macro name="pa10_blue_forearm" params="child" >
    <!-- W1: Wrist flex -->
    <link name="pa10_blue_wrist_flex_link">
      <inertial>
        <origin xyz="0 0 1" rpy="0 0 0"/>
        <mass value="1"/>
        <inertia ixx="1" ixy="0.0" ixz="0.0" iyy="1" iyz="0.0" izz="1"/>
      </inertial>
      <visual>
        <origin xyz="0 0 0.195" rpy="0 0 0"/>
        <geometry>
          <mesh filename="package://aurobot_description/meshes/pa10-blue/forearm/W1.stl"/>
        </geometry>
        <material name="white"/>
      </visual>
      <collision>
        <origin xyz="0 0 0.195" rpy="0 0 0"/>
        <geometry>
          <mesh filename="package://aurobot_description/meshes/pa10-blue/forearm/W1_collision.stl"/>
        </geometry>
      </collision>
    </link>
    <joint name="pa10_blue_wrist_flex_joint" type="revolute">
      <parent link="pa10_blue_wrist_flex_link"/>
      <child link="pa10_blue_wrist_roll_link"/>
      <origin xyz="0 0 0.195" rpy="0 0 0"/>
      <axis xyz="0 1 0"/>
      <limit effort="1000.0" lower="-2.878" upper="2.878" velocity="0.628"/>
    </joint>
    
    <!-- W2: Wrist roll -->
    <link name="pa10_blue_wrist_roll_link">
      <inertial>
        <origin xyz="0 0 1" rpy="0 0 0"/>
        <mass value="1"/>
        <inertia ixx="1" ixy="0.0" ixz="0.0" iyy="1" iyz="0.0" izz="1"/>
      </inertial>
      <visual>
        <origin xyz="0 0 0" rpy="0 0 0"/>
        <geometry>
          <mesh filename="package://aurobot_description/meshes/pa10-blue/forearm/W2.stl"/>
        </geometry>
        <material name="blue"/>
      </visual>
      <collision>
        <origin xyz="0 0 0" rpy="0 0 0"/>
        <geometry>
          <mesh filename="package://aurobot_description/meshes/pa10-blue/forearm/W2_collision.stl"/>
        </geometry>
      </collision>
    </link>
    <joint name="pa10_blue_wrist_roll_joint" type="revolute">
      <parent link="pa10_blue_wrist_roll_link"/>
      <child link="${child}"/>
      <origin xyz="0 0 0.075" rpy="0 0 0"/>
      <axis xyz="0 0 1"/>
      <limit effort="1000.0" lower="-2.878" upper="2.878" velocity="0.628"/>
    </joint>

    <!-- extensions-->
    <xacro:pa10_blue_forearm_gazebo/>
    <xacro:pa10_blue_forearm_transmission/>
  </xacro:macro>
</robot>