<?xml version="1.0"?>

<!-- XML namespaces -->
<robot xmlns:sensor="http://playerstage.sourceforge.net/gazebo/xmlschema/#sensor"
       xmlns:controller="http://playerstage.sourceforge.net/gazebo/xmlschema/#controller"
       xmlns:interface="http://playerstage.sourceforge.net/gazebo/xmlschema/#interface"
       xmlns:xacro="http://ros.org/wiki/xacro">

  <!-- Things that are needed only for Gazebo (not the physical robot).  These include
       sensor and controller plugin specifications -->
  <xacro:include filename="$(find aurobot_description)/urdf/pa10-blue/shoulder/shoulder.gazebo.xacro"/>
  <xacro:include filename="$(find aurobot_description)/urdf/pa10-blue/shoulder/shoulder.transmission.xacro"/>
  <xacro:include filename="$(find aurobot_description)/urdf/common.xacro"/>

 <!-- ============================   Shoulder   ============================ -->

  <xacro:macro name="pa10_blue_shoulder" params="child">
    <!-- S1: Shoulder roll -->
    <link name="pa10_blue_shoulder_roll_link">
      <inertial>
        <origin xyz="0 0 1" rpy="0 0 0"/>
        <mass value="1"/>
        <inertia ixx="1" ixy="0.0" ixz="0.0" iyy="1" iyz="0.0" izz="1"/>
      </inertial>
      <visual>
        <origin xyz="0 0 0" rpy="0 0 3.14"/>
        <geometry>
            <mesh filename="package://aurobot_description/meshes/pa10-blue/shoulder/S1.stl"/>
        </geometry>
        <material name="">
          <color rgba="0.34 0.35 0.36 1.0"/>
        </material>
      </visual>
      <collision>
        <origin xyz="0 0 0" rpy="0 0 3.14"/>
        <geometry>
          <mesh filename="package://aurobot_description/meshes/pa10-blue/shoulder/S1_collision.stl"/>
        </geometry>
      </collision>
    </link>
    <joint name="pa10_blue_shoulder_roll_joint" type="revolute">
      <parent link="pa10_blue_shoulder_roll_link"/>
      <child link="pa10_blue_shoulder_lift_link"/>
      <origin xyz="0 0 0.2" rpy="0 0 0"/>
      <axis xyz="0 0 1"/>
      <limit effort="0" lower="-3.089" upper="3.089" velocity="1.0"/>
    </joint>
    
    <!-- S2: Shoulder lift -->
    <link name="pa10_blue_shoulder_lift_link"> 
      <inertial>
        <origin xyz="0 0 1" rpy="0 0 0"/>
        <mass value="1"/>
        <inertia ixx="1" ixy="0.0" ixz="0.0" iyy="1" iyz="0.0" izz="1"/>
      </inertial>
      <visual>
        <origin xyz="0 0 0.117" rpy="0 0 0"/>
        <geometry>
          <mesh filename="package://aurobot_description/meshes/pa10-blue/shoulder/S2.stl"/>
        </geometry>
        <material name="">
          <color rgba="0.33 0.96 0.53 1.5"/>
        </material>
      </visual>
      <collision>
        <origin xyz="0 0 0.117" rpy="0 0 0"/>
        <geometry>
          <mesh filename="package://aurobot_description/meshes/pa10-blue/shoulder/S2_collision.stl"/>
        </geometry>
      </collision>
    </link>
    <joint name="pa10_blue_shoulder_lift_joint" type="revolute">
      <parent link="pa10_blue_shoulder_lift_link"/>
      <child link="pa10_blue_upper_arm_roll_link"/>
      <origin xyz="0 0 0.117" rpy="0 0 0"/>
      <axis xyz="0 1 0"/>
      <limit effort="0" lower="-1.64" upper="1.64" velocity="1.0"/>
    </joint>
    
    <!-- S3: Upperarm roll -->
    <link name="pa10_blue_upper_arm_roll_link">
      <inertial>
        <origin xyz="0 0 1" rpy="0 0 0"/>
        <mass value="1"/>
        <inertia ixx="1" ixy="0.0" ixz="0.0" iyy="1" iyz="0.0" izz="1"/>
      </inertial>
      <visual>
        <origin xyz="0 0 0" rpy="0 0 0"/>
        <geometry>
          <mesh filename="package://aurobot_description/meshes/pa10-blue/shoulder/S3.stl"/>
        </geometry>
        <material name="">
          <color rgba="0.34 0.35 0.36 1.0"/>
        </material>
      </visual>
      <collision>
        <origin xyz="0 0 0" rpy="0 0 0"/>
        <geometry>
          <mesh filename="package://aurobot_description/meshes/pa10-blue/shoulder/S3_collision.stl"/>
        </geometry>
      </collision>
    </link>
    <joint name="pa10_blue_upper_arm_roll_joint" type="revolute">
      <parent link="pa10_blue_upper_arm_roll_link"/>
      <child link="${child}"/>
      <origin xyz="0 0 0.317" rpy="0 0 0"/>
      <axis xyz="0 0 1"/>
      <limit effort="0" lower="-3.036" upper="3.036" velocity="1.0"/>
    </joint>

    <!-- extensions -->
    <xacro:pa10_blue_shoulder_gazebo/>
    <xacro:pa10_blue_shoulder_transmission/>
  </xacro:macro>
</robot>
