<?xml version="1.0"?>

<!-- XML namespaces -->
<robot xmlns:sensor="http://playerstage.sourceforge.net/gazebo/xmlschema/#sensor"
       xmlns:controller="http://playerstage.sourceforge.net/gazebo/xmlschema/#controller"
       xmlns:interface="http://playerstage.sourceforge.net/gazebo/xmlschema/#interface"
       xmlns:xacro="http://ros.org/wiki/xacro">

  <!-- Things that are needed only for Gazebo (not the physical robot). These include
       sensor and controller plugin specifications -->
  <xacro:include filename="$(find aurobot_description)/urdf/forearm/forearm.gazebo.xacro"/>
  <xacro:include filename="$(find aurobot_description)/urdf/forearm/forearm.transmission.xacro"/>
  <xacro:include filename="$(find aurobot_description)/urdf/common.xacro"/>

  <!-- ============================   Forearm   ============================ -->

  <xacro:macro name="pa10_forearm" params="side child" >
    <!-- W1: Wrist flex -->
    <link name="${side}_wrist_flex_link">
      <inertial>
        <origin xyz="0 -0.0432 0.03" rpy="0 0 0"/>
        <mass value="3.45"/>
        <inertia ixx="0.076687"  ixy="0.000005"  ixz="0.000960" iyy="0.077392" iyz="0.000005" izz="0.006233"/>
      </inertial>
      <visual>
        <origin xyz="0 0 0.03" rpy="0 0 0"/>
        <geometry>
          <mesh filename="package://aurobot_description/meshes/forearm/W1.dae"/>
        </geometry>
        <material name="green"/>
      </visual>
      <collision>
        <origin xyz="0 0 0.03" rpy="0 0 0"/>
        <geometry>
          <mesh filename="package://aurobot_description/meshes/forearm/W1.stl"/>
        </geometry>
      </collision>
    </link>
    <joint name="${side}_wrist_flex_joint" type="revolute">
      <parent link="${side}_wrist_flex_link"/>
      <child link="${side}_wrist_roll_link"/>
      <origin xyz="0 0 0.05" rpy="0 0 0"/>
      <axis xyz="0 1 0"/>
      <limit effort="1000.0" lower="-2.88" upper="2.88" velocity="0.628"/>
      <cfm>0.7</cfm>
    </joint>
    
    <!-- W2: Wrist roll -->
    <link name="${side}_wrist_roll_link">
      <inertial>
        <origin xyz="0 0.003 -0.0175" rpy="0 0 0"/>
        <mass value="1.46"/>
        <inertia ixx="0.012500"  ixy="0.000005"  ixz="0.000005" iyy="0.011431" iyz="0.000005" izz="0.012500"/>
      </inertial>
      <visual>
        <origin xyz="0 0.0 -0.0175" rpy="0 0 0"/>
        <geometry>
          <mesh filename="package://aurobot_description/meshes/forearm/W2.dae"/>
        </geometry>
        <material name="blue"/>
      </visual>
      <collision>
        <origin xyz="0 0.0 -0.0175" rpy="0 0 0"/>
        <geometry>
          <mesh filename="package://aurobot_description/meshes/forearm/W2.stl"/>
        </geometry>
      </collision>
    </link>
    <joint name="${side}_wrist_roll_joint" type="revolute">
      <parent link="${side}_wrist_roll_link"/>
      <child link="${child}"/>
      <origin xyz="0 0 0.050" rpy="0 0 0"/>
      <axis xyz="0 0 1"/>
      <limit effort="1000.0" lower="-2.0" upper="2.28" velocity="0.628"/>
      <cfm>0.7</cfm>
    </joint>

    <!-- extensions-->
    <xacro:pa10_forearm_gazebo side="${side}"/>
    <xacro:pa10_forearm_transmission side="${side}"/>
  </xacro:macro>
</robot>