<?xml version="1.0"?>

<!-- XML namespaces -->
<robot xmlns:sensor="http://playerstage.sourceforge.net/gazebo/xmlschema/#sensor"
       xmlns:controller="http://playerstage.sourceforge.net/gazebo/xmlschema/#controller"
       xmlns:interface="http://playerstage.sourceforge.net/gazebo/xmlschema/#interface"
       xmlns:xacro="http://ros.org/wiki/xacro">

  <!-- Things that are needed only for Gazebo (not the physical robot). These include
       sensor and controller plugin specifications -->
  <xacro:include filename="$(find aurobot_description)/urdf/pa10-green/forearm/forearm.gazebo.xacro"/>
  <xacro:include filename="$(find aurobot_description)/urdf/pa10-green/forearm/forearm.transmission.xacro"/>
  <xacro:include filename="$(find aurobot_description)/urdf/common.xacro"/>

  <!-- ============================   Forearm   ============================ -->
  <!-- BRAYAN (22/11/2017): Dejamos origin a 0,0,0 en todo lo que no sea joint -->

  <xacro:macro name="pa10_green_forearm" params="child" >
    <!-- W1: Wrist flex -->
    <link name="pa10_green_wrist_flex_link">
      <inertial>
        <mass value="3.45"/>
        <origin xyz="0 0 0" rpy="0 0 0"/>
        <inertia ixx="0.076687"  ixy="0.000005"  ixz="0.000960" iyy="0.077392" iyz="0.000005" izz="0.006233"/>
      </inertial>
      <visual>
        <geometry>
          <mesh filename="package://aurobot_description/meshes/pa10-green/forearm/pa10_05.stl"/>
        </geometry>
        <material name="green"/>
      </visual>
      <collision>
        <geometry>
          <mesh filename="package://aurobot_description/meshes/pa10-green/forearm/pa10_05.stl"/>
        </geometry>
      </collision>
    </link>
    <joint name="pa10_green_wrist_flex_joint" type="revolute">
      <parent link="pa10_green_wrist_flex_link"/>
      <child link="pa10_green_wrist_roll_link"/>
      <!-- BRAYAN (22/11/2017): Recalculo mas preciso <origin xyz="0 0 0.05" rpy="0 0 0"/> -->
      <origin xyz="0 0 0.23643" rpy="0 0 0"/>
      <axis xyz="0 1 0"/>
      <limit effort="1000.0" lower="-2.8797932658" upper="2.8797932658" velocity="0.628"/>
      <cfm>0.7</cfm>
    </joint>
    
    <!-- W2: Wrist roll -->
    <link name="pa10_green_wrist_roll_link">
      <inertial>
        <mass value="1.46"/>
        <origin xyz="0 0 0" rpy="0 0 0"/>
        <inertia ixx="0.012500"  ixy="0.000005"  ixz="0.000005" iyy="0.011431" iyz="0.000005" izz="0.012500"/>
      </inertial>
      <visual>
        <geometry>
          <mesh filename="package://aurobot_description/meshes/pa10-green/forearm/pa10_06.stl"/>
        </geometry>
        <material name="blue"/>
      </visual>
      <collision>
        <geometry>
          <mesh filename="package://aurobot_description/meshes/pa10-green/forearm/pa10_06.stl"/>
        </geometry>
      </collision>
    </link>
    <joint name="pa10_green_wrist_roll_joint" type="revolute">
      <parent link="pa10_green_wrist_roll_link"/>
      <child link="${child}"/>
      <!-- BRAYAN (12/07/2017): Segun el manual nos falta 0.03 <origin xyz="0 0 0.050" rpy="0 0 0"/> -->
      <origin xyz="0 0 0.080" rpy="0 0 0"/>
      <axis xyz="0 0 1"/>
      <!-- BRAYAN (13/07/2017): gran cambio en lower y upper, casi el doble hemos puesto -->
      <limit effort="1000.0" lower="-6.2831853072" upper="6.2831853072" velocity="0.628"/>
      <cfm>0.7</cfm>
    </joint>

    <!-- extensions-->
    <xacro:pa10_green_forearm_gazebo/>
    <xacro:pa10_green_forearm_transmission/>
  </xacro:macro>
</robot>